   cfg_dict, cfg_text = Config._file2dict(filename,
  File "/home/shouvon/miniconda3/envs/cfinet/lib/python3.8/site-packages/mmcv/utils/config.py", line 182, in _file2dict
    check_file_exist(filename)
  File "/home/shouvon/miniconda3/envs/cfinet/lib/python3.8/site-packages/mmcv/utils/path.py", line 23, in check_file_exist
    raise FileNotFoundError(msg_tmpl.format(filename))
FileNotFoundError: file "/home/shouvon/CFINet/work_dirs/cfinet_sodad/cfinet_r50_1x_soda.py" does not exist
Traceback (most recent call last):
  File "tools/train.py", line 247, in <module>
    main()
  File "tools/train.py", line 111, in main
    cfg = Config.fromfile(args.config)
  File "/home/shouvon/miniconda3/envs/cfinet/lib/python3.8/site-packages/mmcv/utils/config.py", line 337, in fromfile
    cfg_dict, cfg_text = Config._file2dict(filename,
  File "/home/shouvon/miniconda3/envs/cfinet/lib/python3.8/site-packages/mmcv/utils/config.py", line 182, in _file2dict
    check_file_exist(filename)
  File "/home/shouvon/miniconda3/envs/cfinet/lib/python3.8/site-packages/mmcv/utils/path.py", line 23, in check_file_exist
    raise FileNotFoundError(msg_tmpl.format(filename))
FileNotFoundError: file "/home/shouvon/CFINet/work_dirs/cfinet_sodad/cfinet_r50_1x_soda.py" does not exist
Traceback (most recent call last):
  File "tools/train.py", line 247, in <module>
    main()
  File "tools/train.py", line 111, in main
    cfg = Config.fromfile(args.config)
  File "/home/shouvon/miniconda3/envs/cfinet/lib/python3.8/site-packages/mmcv/utils/config.py", line 337, in fromfile
    cfg_dict, cfg_text = Config._file2dict(filename,
  File "/home/shouvon/miniconda3/envs/cfinet/lib/python3.8/site-packages/mmcv/utils/config.py", line 182, in _file2dict
    check_file_exist(filename)
  File "/home/shouvon/miniconda3/envs/cfinet/lib/python3.8/site-packages/mmcv/utils/path.py", line 23, in check_file_exist
    raise FileNotFoundError(msg_tmpl.format(filename))
FileNotFoundError: file "/home/shouvon/CFINet/work_dirs/cfinet_sodad/cfinet_r50_1x_soda.py" does not exist
ERROR:torch.distributed.elastic.multiprocessing.api:failed (exitcode: 1) local_rank: 0 (pid: 23150) of binary: /home/shouvon/miniconda3/envs/cfinet/bin/python
Traceback (most recent call last):
  File "/home/shouvon/miniconda3/envs/cfinet/lib/python3.8/runpy.py", line 194, in _run_module_as_main
    return _run_code(code, main_globals, None,
  File "/home/shouvon/miniconda3/envs/cfinet/lib/python3.8/runpy.py", line 87, in _run_code
    exec(code, run_globals)
  File "/home/shouvon/miniconda3/envs/cfinet/lib/python3.8/site-packages/torch/distributed/launch.py", line 193, in <module>
    main()
  File "/home/shouvon/miniconda3/envs/cfinet/lib/python3.8/site-packages/torch/distributed/launch.py", line 189, in main
    launch(args)
  File "/home/shouvon/miniconda3/envs/cfinet/lib/python3.8/site-packages/torch/distributed/launch.py", line 174, in launch
    run(args)
  File "/home/shouvon/miniconda3/envs/cfinet/lib/python3.8/site-packages/torch/distributed/run.py", line 710, in run
    elastic_launch(
  File "/home/shouvon/miniconda3/envs/cfinet/lib/python3.8/site-packages/torch/distributed/launcher/api.py", line 131, in __call__
    return launch_agent(self._config, self._entrypoint, list(args))
  File "/home/shouvon/miniconda3/envs/cfinet/lib/python3.8/site-packages/torch/distributed/launcher/api.py", line 259, in launch_agent
    raise ChildFailedError(
torch.distributed.elastic.multiprocessing.errors.ChildFailedError:
============================================================
tools/train.py FAILED
------------------------------------------------------------
Failures:
[1]:
  time      : 2025-06-26_01:17:02
  host      : dxs4-DGX-Station
  rank      : 1 (local_rank: 1)
  exitcode  : 1 (pid: 23151)
  error_file: <N/A>
  traceback : To enable traceback see: https://pytorch.org/docs/stable/elastic/errors.html
[2]:
  time      : 2025-06-26_01:17:02
  host      : dxs4-DGX-Station
  rank      : 2 (local_rank: 2)
  exitcode  : 1 (pid: 23152)
  error_file: <N/A>
  traceback : To enable traceback see: https://pytorch.org/docs/stable/elastic/errors.html
[3]:
  time      : 2025-06-26_01:17:02
  host      : dxs4-DGX-Station
  rank      : 3 (local_rank: 3)
  exitcode  : 1 (pid: 23153)
  error_file: <N/A>
  traceback : To enable traceback see: https://pytorch.org/docs/stable/elastic/errors.html
------------------------------------------------------------
Root Cause (first observed failure):
[0]:
  time      : 2025-06-26_01:17:02
  host      : dxs4-DGX-Station
  rank      : 0 (local_rank: 0)
  exitcode  : 1 (pid: 23150)
  error_file: <N/A>
  traceback : To enable traceback see: https://pytorch.org/docs/stable/elastic/errors.html
